Workbook
Name NativeTimeline_Leased_Date: #N/A
Name Scenario: #REF!
Name Slicer_Baths: #N/A
Name Slicer_Beds: #N/A
Name Slicer_Beds1: #N/A
Name Slicer_Property_Name: #N/A
Name Slicer_Property_Name1: #N/A

Sheet Intro
B7: Click "Enable Editing" to update.
B9: Table of Contents
B11: 1 | C11: Weekly Market Updates
B12: 2 | C12: 30-Day Trends
B13: 3 | C13: Data Analysis
B14: 4 | C14: Leasing Trends
B15: 5 | C15: Rent Comps
B16: 6 | C16: Rent Comparison
B17: 7 | C17: Rents by Unit Type
B18: 8 | C18: Unit-Level Data
B19: 9 | C19: Unit Mix
B20: 10 | C20: Reviews Analysis
B21: 11 | C21: Fees & Amenities
B22: 12 | C22: Specials
B24: © 2025 Hello Data, Inc. All rights reserved.
B25: This spreadsheet and its contents are proprietary and confidential. Unauthorized reproduction, distribution, or use of this template, including for the development of competing software products or services, is strictly prohibited.

Sheet Weekly Market Updates
B2: Weekly Market Updates | P2: Week Ending: | Q2: 45978
B3: Note: Delta (△) figures show change from previous 7-day period.
B5: Property | C5: Active Concessions | E5: Type | F5: # Leased | G5: △ | H5: Leased Rents | I5: $△ | J5: %△ | K5: # New | L5: △ | M5: New Listing Rents | N5: # Active | O5: △ | P5: Asking Rents | Q5: Exposure
B6: =IF(OFFSET('Rent Comparison'!$A$1,2,2)="{{subject.building_name}}","",IF(OFFSET('Rent Comparison'!$A$1,2,2)=0,B7,OFFSET('Rent Comparison'!$A$1,2,2))) -> Grand Mesa Flats | C6: =IF(ISBLANK(B6),"",IFERROR(INDEX(Specials!B:J,MATCH(B6&" - Active",Specials!I:I,0),2),"")) | E6: Studio | F6: =COUNTIFS(unit_details[Leased Date], ">=" & ($Q$2 - 7), unit_details[Leased Date], "<" & $Q$2, unit_details[Beds], 0, unit_details[Property Name], B6) -> 0 | G6: =COUNTIFS(unit_details[Leased Date], ">=" & ($Q$2 - 7), unit_details[Leased Date], "<" & $Q$2, unit_details[Beds], 0, unit_details[Property Name], B6) - COUNTIFS(unit_details[Leased Date], ">=" & ($Q$2 - 14), unit_details[Leased Date], "<=" & ($Q$2 - 7), unit_details[Beds], 0, unit_details[Property Name], B6) -> 0 | H6: =IFERROR(AVERAGEIFS( unit_details[Asking Rent], unit_details[Leased Date], ">=" & ($Q$2 - 7), unit_details[Leased Date], "<" & $Q$2, unit_details[Beds], 0, unit_details[Property Name], B6),"") | I6: =IFERROR( AVERAGEIFS(unit_details[Asking Rent], unit_details[Leased Date], ">=" & ($Q$2 - 7), unit_details[Leased Date], "<" & $Q$2, unit_details[Beds], 0, unit_details[Property Name], B6) - AVERAGEIFS(unit_details[Asking Rent], unit_details[Leased Date], ">=" & ($Q$2 - 14), unit_details[Leased Date], "<=" & ($Q$2 - 7), unit_details[Beds], 0, unit_details[Property Name], B6), 0) -> 0 | J6: =IFERROR(I6/AVERAGEIFS(unit_details[Asking Rent], unit_details[Leased Date], ">=" & ($Q$2 - 14), unit_details[Leased Date], "<=" & ($Q$2 - 7), unit_details[Beds], 0, unit_details[Property Name], B6),0) -> 0 | K6: =COUNTIFS(unit_details[First Listed], ">=" & ($Q$2 - 7), unit_details[First Listed], "<" & $Q$2, unit_details[Beds], 0, unit_details[Property Name], B6) -> 0 | L6: =COUNTIFS( unit_details[First Listed], ">=" & ($Q$2 - 7), unit_details[First Listed], "<" & $Q$2, unit_details[Beds], 0, unit_details[Property Name], B6 ) - COUNTIFS( unit_details[First Listed], ">=" & ($Q$2 - 14), unit_details[First Listed], "<=" & ($Q$2 - 7), unit_details[Beds], 0, unit_details[Property Name], B6 ) -> 0 | M6: =IFERROR(AVERAGEIFS(unit_details[Asking Rent],unit_details[First Listed],">="&($Q$2-7), unit_details[First Listed],"<="&$Q$2, unit_details[Beds],0, unit_details[Property Name],B6),"") | N6: =COUNTIFS(unit_details[Property Name], B6, unit_details[Beds], 0, unit_details[Leased Date], "") -> 0 | O6: =N6-(N6-K6+F6) -> 0 | P6: =IFERROR(AVERAGEIFS(unit_details[Asking Rent],unit_details[Property Name], B6, unit_details[Beds], 0, unit_details[Leased Date], ""),"") | Q6: =IFERROR(N6/SUMIFS(unit_mix_table['# Units],unit_mix_table[Beds],0,unit_mix_table[Property Name],B6),"")
B7: 1681 Rodeo Way, Delta, CO 81416 | E7: 1 BR | F7: =COUNTIFS(unit_details[Leased Date], ">=" & ($Q$2 - 7), unit_details[Leased Date], "<" & $Q$2, unit_details[Beds], 1, unit_details[Property Name], B6) -> 0 | G7: =COUNTIFS(unit_details[Leased Date], ">=" & ($Q$2 - 7), unit_details[Leased Date], "<" & $Q$2, unit_details[Beds], 1, unit_details[Property Name], B6) - COUNTIFS(unit_details[Leased Date], ">=" & ($Q$2 - 14), unit_details[Leased Date], "<=" & ($Q$2 - 7), unit_details[Beds], 1, unit_details[Property Name], B6) -> 0 | H7: =IFERROR(AVERAGEIFS( unit_details[Asking Rent], unit_details[Leased Date], ">=" & ($Q$2 - 7), unit_details[Leased Date], "<" & $Q$2, unit_details[Beds], 1, unit_details[Property Name], B6),"") | I7: =IFERROR( AVERAGEIFS(unit_details[Asking Rent], unit_details[Leased Date], ">=" & ($Q$2 - 7), unit_details[Leased Date], "<" & $Q$2, unit_details[Beds], 1, unit_details[Property Name], B6) - AVERAGEIFS(unit_details[Asking Rent], unit_details[Leased Date], ">=" & ($Q$2 - 14), unit_details[Leased Date], "<=" & ($Q$2 - 7), unit_details[Beds], 1, unit_details[Property Name], B6), 0) -> 0 | J7: =IFERROR(I7/AVERAGEIFS(unit_details[Asking Rent], unit_details[Leased Date], ">=" & ($Q$2 - 14), unit_details[Leased Date], "<=" & ($Q$2 - 7), unit_details[Beds], 1, unit_details[Property Name], B6),0) -> 0 | K7: =COUNTIFS(unit_details[First Listed], ">=" & ($Q$2 - 7), unit_details[First Listed], "<" & $Q$2, unit_details[Beds], 1, unit_details[Property Name], B6) -> 0 | L7: =COUNTIFS( unit_details[First Listed], ">=" & ($Q$2 - 7), unit_details[First Listed], "<" & $Q$2, unit_details[Beds], 1, unit_details[Property Name], B6 ) - COUNTIFS( unit_details[First Listed], ">=" & ($Q$2 - 14), unit_details[First Listed], "<=" & ($Q$2 - 7), unit_details[Beds], 1, unit_details[Property Name], B6 ) -> 0 | M7: =IFERROR(AVERAGEIFS(unit_details[Asking Rent],unit_details[First Listed],">="&($Q$2-7), unit_details[First Listed],"<="&$Q$2, unit_details[Beds],1, unit_details[Property Name],B6),"") | N7: =COUNTIFS(unit_details[Property Name], B6, unit_details[Beds], 1, unit_details[Leased Date], "") -> 0 | O7: =N7-(N7-K7+F7) -> 0 | P7: =IFERROR(AVERAGEIFS(unit_details[Asking Rent],unit_details[Property Name], B6, unit_details[Beds], 1, unit_details[Leased Date], ""),"") | Q7: =IFERROR(N7/SUMIFS(unit_mix_table['# Units],unit_mix_table[Beds],1,unit_mix_table[Property Name],B6),"")
E8: 2 BR | F8: =COUNTIFS(unit_details[Leased Date], ">=" & ($Q$2 - 7), unit_details[Leased Date], "<" & $Q$2, unit_details[Beds], 2, unit_details[Property Name], B6) -> 1 | G8: =COUNTIFS(unit_details[Leased Date], ">=" & ($Q$2 - 7), unit_details[Leased Date], "<" & $Q$2, unit_details[Beds], 2, unit_details[Property Name], B6) - COUNTIFS(unit_details[Leased Date], ">=" & ($Q$2 - 14), unit_details[Leased Date], "<=" & ($Q$2 - 7), unit_details[Beds], 2, unit_details[Property Name], B6) -> 1 | H8: =IFERROR(AVERAGEIFS( unit_details[Asking Rent], unit_details[Leased Date], ">=" & ($Q$2 - 7), unit_details[Leased Date], "<" & $Q$2, unit_details[Beds], 2, unit_details[Property Name], B6),"") -> 1490 | I8: =IFERROR( AVERAGEIFS(unit_details[Asking Rent], unit_details[Leased Date], ">=" & ($Q$2 - 7), unit_details[Leased Date], "<" & $Q$2, unit_details[Beds], 2, unit_details[Property Name], B6) - AVERAGEIFS(unit_details[Asking Rent], unit_details[Leased Date], ">=" & ($Q$2 - 14), unit_details[Leased Date], "<=" & ($Q$2 - 7), unit_details[Beds], 2, unit_details[Property Name], B6), 0) -> 0 | J8: =IFERROR(I8/AVERAGEIFS(unit_details[Asking Rent], unit_details[Leased Date], ">=" & ($Q$2 - 14), unit_details[Leased Date], "<=" & ($Q$2 - 7), unit_details[Beds], 2, unit_details[Property Name], B6),0) -> 0 | K8: =COUNTIFS(unit_details[First Listed], ">=" & ($Q$2 - 7), unit_details[First Listed], "<" & $Q$2, unit_details[Beds], 2, unit_details[Property Name], B6) -> 0 | L8: =COUNTIFS( unit_details[First Listed], ">=" & ($Q$2 - 7), unit_details[First Listed], "<" & $Q$2, unit_details[Beds], 2, unit_details[Property Name], B6 ) - COUNTIFS( unit_details[First Listed], ">=" & ($Q$2 - 14), unit_details[First Listed], "<=" & ($Q$2 - 7), unit_details[Beds], 2, unit_details[Property Name], B6 ) -> 0 | M8: =IFERROR(AVERAGEIFS(unit_details[Asking Rent],unit_details[First Listed],">="&($Q$2-7), unit_details[First Listed],"<="&$Q$2, unit_details[Beds],2, unit_details[Property Name],B6),"") | N8: =COUNTIFS(unit_details[Property Name], B6, unit_details[Beds], 2, unit_details[Leased Date], "") -> 4 | O8: =N8-(N8-K8+F8) -> -1 | P8: =IFERROR(AVERAGEIFS(unit_details[Asking Rent],unit_details[Property Name], B6, unit_details[Beds], 2, unit_details[Leased Date], ""),"") -> 1425 | Q8: =IFERROR(N8/SUMIFS(unit_mix_table['# Units],unit_mix_table[Beds],2,unit_mix_table[Property Name],B6),"")
E9: 3 BR | F9: =COUNTIFS(unit_details[Leased Date], ">=" & ($Q$2 - 7), unit_details[Leased Date], "<" & $Q$2, unit_details[Beds], 3, unit_details[Property Name], B6) -> 0 | G9: =COUNTIFS(unit_details[Leased Date], ">=" & ($Q$2 - 7), unit_details[Leased Date], "<" & $Q$2, unit_details[Beds], 3, unit_details[Property Name], B6) - COUNTIFS(unit_details[Leased Date], ">=" & ($Q$2 - 14), unit_details[Leased Date], "<=" & ($Q$2 - 7), unit_details[Beds], 3, unit_details[Property Name], B6) -> 0 | H9: =IFERROR(AVERAGEIFS( unit_details[Asking Rent], unit_details[Leased Date], ">=" & ($Q$2 - 7), unit_details[Leased Date], "<" & $Q$2, unit_details[Beds], 3, unit_details[Property Name], B6),"") | I9: =IFERROR( AVERAGEIFS(unit_details[Asking Rent], unit_details[Leased Date], ">=" & ($Q$2 - 7), unit_details[Leased Date], "<" & $Q$2, unit_details[Beds], 3, unit_details[Property Name], B6) - AVERAGEIFS(unit_details[Asking Rent], unit_details[Leased Date], ">=" & ($Q$2 - 14), unit_details[Leased Date], "<=" & ($Q$2 - 7), unit_details[Beds], 3, unit_details[Property Name], B6), 0) -> 0 | J9: =IFERROR(I9/AVERAGEIFS(unit_details[Asking Rent], unit_details[Leased Date], ">=" & ($Q$2 - 14), unit_details[Leased Date], "<=" & ($Q$2 - 7), unit_details[Beds], 3, unit_details[Property Name], B6),0) -> 0 | K9: =COUNTIFS(unit_details[First Listed], ">=" & ($Q$2 - 7), unit_details[First Listed], "<" & $Q$2, unit_details[Beds], 3, unit_details[Property Name], B6) -> 0 | L9: =COUNTIFS( unit_details[First Listed], ">=" & ($Q$2 - 7), unit_details[First Listed], "<" & $Q$2, unit_details[Beds], 3, unit_details[Property Name], B6 ) - COUNTIFS( unit_details[First Listed], ">=" & ($Q$2 - 14), unit_details[First Listed], "<=" & ($Q$2 - 7), unit_details[Beds], 3, unit_details[Property Name], B6 ) -> 0 | M9: =IFERROR(AVERAGEIFS(unit_details[Asking Rent],unit_details[First Listed],">="&($Q$2-7), unit_details[First Listed],"<="&$Q$2, unit_details[Beds],3, unit_details[Property Name],B6),"") | N9: =COUNTIFS(unit_details[Property Name], B6, unit_details[Beds], 3, unit_details[Leased Date], "") -> 0 | O9: =N9-(N9-K9+F9) -> 0 | P9: =IFERROR(AVERAGEIFS(unit_details[Asking Rent],unit_details[Property Name], B6, unit_details[Beds], 3, unit_details[Leased Date], ""),"") | Q9: =IFERROR(N9/SUMIFS(unit_mix_table['# Units],unit_mix_table[Beds],3,unit_mix_table[Property Name],B6),"")
B10: =IF(OFFSET('Rent Comparison'!$A$1,2,6)="{{h:comparables.#.building_name}}","",IF(OFFSET('Rent Comparison'!$A$1,2,6)=0,B11,OFFSET('Rent Comparison'!$A$1,2,6))) -> 211 Rich Street, Delta, CO 81416 | C10: =IF(ISBLANK(B10),"",IFERROR(INDEX(Specials!B:J,MATCH(B10&" - Active",Specials!I:I,0),2),"")) | E10: Studio | F10: =COUNTIFS(unit_details[Leased Date], ">=" & ($Q$2 - 7), unit_details[Leased Date], "<" & $Q$2, unit_details[Beds], 0, unit_details[Property Name], B10) -> 0 | G10: =COUNTIFS(unit_details[Leased Date], ">=" & ($Q$2 - 7), unit_details[Leased Date], "<" & $Q$2, unit_details[Beds], 0, unit_details[Property Name], B10) - COUNTIFS(unit_details[Leased Date], ">=" & ($Q$2 - 14), unit_details[Leased Date], "<=" & ($Q$2 - 7), unit_details[Beds], 0, unit_details[Property Name], B10) -> 0 | H10: =IFERROR(AVERAGEIFS(unit_details[Asking Rent],unit_details[Leased Date], ">=" & ($Q$2 - 7), unit_details[Leased Date], "<" & $Q$2, unit_details[Beds], 0, unit_details[Property Name], B10),"") | I10: =IFERROR( AVERAGEIFS(unit_details[Asking Rent], unit_details[Leased Date], ">=" & ($Q$2 - 7), unit_details[Leased Date], "<" & $Q$2, unit_details[Beds], 0, unit_details[Property Name], B10) - AVERAGEIFS(unit_details[Asking Rent], unit_details[Leased Date], ">=" & ($Q$2 - 14), unit_details[Leased Date], "<=" & ($Q$2 - 7), unit_details[Beds], 0, unit_details[Property Name], B10), 0) -> 0 | J10: =IFERROR(I10/AVERAGEIFS(unit_details[Asking Rent], unit_details[Leased Date], ">=" & ($Q$2 - 14), unit_details[Leased Date], "<=" & ($Q$2 - 7), unit_details[Beds], 0, unit_details[Property Name], B10),0) -> 0 | K10: =COUNTIFS(unit_details[First Listed], ">=" & ($Q$2 - 7), unit_details[First Listed], "<" & $Q$2, unit_details[Beds], 0, unit_details[Property Name], B10) -> 0 | L10: =COUNTIFS( unit_details[First Listed], ">=" & ($Q$2 - 7), unit_details[First Listed], "<" & $Q$2, unit_details[Beds], 0, unit_details[Property Name], B10 ) - COUNTIFS( unit_details[First Listed], ">=" & ($Q$2 - 14), unit_details[First Listed], "<=" & ($Q$2 - 7), unit_details[Beds], 0, unit_details[Property Name], B10 ) -> 0 | M10: =IFERROR(AVERAGEIFS(unit_details[Asking Rent],unit_details[First Listed],">="&($Q$2-7), unit_details[First Listed],"<="&$Q$2, unit_details[Beds],0, unit_details[Property Name],B10),"") | N10: =COUNTIFS(unit_details[Property Name], B10, unit_details[Beds], 0, unit_details[Leased Date], "") -> 0 | O10: =N10-(N10-K10+F10) -> 0 | P10: =IFERROR(AVERAGEIFS(unit_details[Asking Rent],unit_details[Property Name], B10, unit_details[Beds], 0, unit_details[Leased Date], ""),"") | Q10: =IFERROR(N10/SUMIFS(unit_mix_table['# Units],unit_mix_table[Beds],0,unit_mix_table[Property Name],B10),"")
B11: 211 Rich Street, Delta, CO 81416 | E11: 1 BR | F11: =COUNTIFS(unit_details[Leased Date], ">=" & ($Q$2 - 7), unit_details[Leased Date], "<" & $Q$2, unit_details[Beds], 1, unit_details[Property Name], B10) -> 0 | G11: =COUNTIFS(unit_details[Leased Date], ">=" & ($Q$2 - 7), unit_details[Leased Date], "<" & $Q$2, unit_details[Beds], 1, unit_details[Property Name], B10) - COUNTIFS(unit_details[Leased Date], ">=" & ($Q$2 - 14), unit_details[Leased Date], "<=" & ($Q$2 - 7), unit_details[Beds], 1, unit_details[Property Name], B10) -> 0 | H11: =IFERROR(AVERAGEIFS(unit_details[Asking Rent],unit_details[Leased Date], ">=" & ($Q$2 - 7), unit_details[Leased Date], "<" & $Q$2, unit_details[Beds], 1, unit_details[Property Name], B10),"") | I11: =IFERROR( AVERAGEIFS(unit_details[Asking Rent], unit_details[Leased Date], ">=" & ($Q$2 - 7), unit_details[Leased Date], "<" & $Q$2, unit_details[Beds], 1, unit_details[Property Name], B10) - AVERAGEIFS(unit_details[Asking Rent], unit_details[Leased Date], ">=" & ($Q$2 - 14), unit_details[Leased Date], "<=" & ($Q$2 - 7), unit_details[Beds], 1, unit_details[Property Name], B10), 0) -> 0 | J11: =IFERROR(I11/AVERAGEIFS(unit_details[Asking Rent], unit_details[Leased Date], ">=" & ($Q$2 - 14), unit_details[Leased Date], "<=" & ($Q$2 - 7), unit_details[Beds], 1, unit_details[Property Name], B10),0) -> 0 | K11: =COUNTIFS(unit_details[First Listed], ">=" & ($Q$2 - 7), unit_details[First Listed], "<" & $Q$2, unit_details[Beds], 1, unit_details[Property Name], B10) -> 0 | L11: =COUNTIFS( unit_details[First Listed], ">=" & ($Q$2 - 7), unit_details[First Listed], "<" & $Q$2, unit_details[Beds], 1, unit_details[Property Name], B10 ) - COUNTIFS( unit_details[First Listed], ">=" & ($Q$2 - 14), unit_details[First Listed], "<=" & ($Q$2 - 7), unit_details[Beds], 1, unit_details[Property Name], B10 ) -> 0 | M11: =IFERROR(AVERAGEIFS(unit_details[Asking Rent],unit_details[First Listed],">="&($Q$2-7), unit_details[First Listed],"<="&$Q$2, unit_details[Beds],1, unit_details[Property Name],B10),"") | N11: =COUNTIFS(unit_details[Property Name], B10, unit_details[Beds], 1, unit_details[Leased Date], "") -> 0 | O11: =N11-(N11-K11+F11) -> 0 | P11: =IFERROR(AVERAGEIFS(unit_details[Asking Rent],unit_details[Property Name], B10, unit_details[Beds], 1, unit_details[Leased Date], ""),"") | Q11: =IFERROR(N11/SUMIFS(unit_mix_table['# Units],unit_mix_table[Beds],1,unit_mix_table[Property Name],B10),"")
E12: 2 BR | F12: =COUNTIFS(unit_details[Leased Date], ">=" & ($Q$2 - 7), unit_details[Leased Date], "<" & $Q$2, unit_details[Beds], 2, unit_details[Property Name], B10) -> 0 | G12: =COUNTIFS(unit_details[Leased Date], ">=" & ($Q$2 - 7), unit_details[Leased Date], "<" & $Q$2, unit_details[Beds], 2, unit_details[Property Name], B10) - COUNTIFS(unit_details[Leased Date], ">=" & ($Q$2 - 14), unit_details[Leased Date], "<=" & ($Q$2 - 7), unit_details[Beds], 2, unit_details[Property Name], B10) -> 0 | H12: =IFERROR(AVERAGEIFS(unit_details[Asking Rent],unit_details[Leased Date], ">=" & ($Q$2 - 7), unit_details[Leased Date], "<" & $Q$2, unit_details[Beds], 2, unit_details[Property Name], B10),"") | I12: =IFERROR( AVERAGEIFS(unit_details[Asking Rent], unit_details[Leased Date], ">=" & ($Q$2 - 7), unit_details[Leased Date], "<" & $Q$2, unit_details[Beds], 2, unit_details[Property Name], B10) - AVERAGEIFS(unit_details[Asking Rent], unit_details[Leased Date], ">=" & ($Q$2 - 14), unit_details[Leased Date], "<=" & ($Q$2 - 7), unit_details[Beds], 2, unit_details[Property Name], B10), 0) -> 0 | J12: =IFERROR(I12/AVERAGEIFS(unit_details[Asking Rent], unit_details[Leased Date], ">=" & ($Q$2 - 14), unit_details[Leased Date], "<=" & ($Q$2 - 7), unit_details[Beds], 2, unit_details[Property Name], B10),0) -> 0 | K12: =COUNTIFS(unit_details[First Listed], ">=" & ($Q$2 - 7), unit_details[First Listed], "<" & $Q$2, unit_details[Beds], 2, unit_details[Property Name], B10) -> 0 | L12: =COUNTIFS( unit_details[First Listed], ">=" & ($Q$2 - 7), unit_details[First Listed], "<" & $Q$2, unit_details[Beds], 2, unit_details[Property Name], B10 ) - COUNTIFS( unit_details[First Listed], ">=" & ($Q$2 - 14), unit_details[First Listed], "<=" & ($Q$2 - 7), unit_details[Beds], 2, unit_details[Property Name], B10 ) -> 0 | M12: =IFERROR(AVERAGEIFS(unit_details[Asking Rent],unit_details[First Listed],">="&($Q$2-7), unit_details[First Listed],"<="&$Q$2, unit_details[Beds],2, unit_details[Property Name],B10),"") | N12: =COUNTIFS(unit_details[Property Name], B10, unit_details[Beds], 2, unit_details[Leased Date], "") -> 0 | O12: =N12-(N12-K12+F12) -> 0 | P12: =IFERROR(AVERAGEIFS(unit_details[Asking Rent],unit_details[Property Name], B10, unit_details[Beds], 2, unit_details[Leased Date], ""),"") | Q12: =IFERROR(N12/SUMIFS(unit_mix_table['# Units],unit_mix_table[Beds],2,unit_mix_table[Property Name],B10),"")
E13: 3 BR | F13: =COUNTIFS(unit_details[Leased Date], ">=" & ($Q$2 - 7), unit_details[Leased Date], "<" & $Q$2, unit_details[Beds], 3, unit_details[Property Name], B10) -> 0 | G13: =COUNTIFS(unit_details[Leased Date], ">=" & ($Q$2 - 7), unit_details[Leased Date], "<" & $Q$2, unit_details[Beds], 3, unit_details[Property Name], B10) - COUNTIFS(unit_details[Leased Date], ">=" & ($Q$2 - 14), unit_details[Leased Date], "<=" & ($Q$2 - 7), unit_details[Beds], 3, unit_details[Property Name], B10) -> 0 | H13: =IFERROR(AVERAGEIFS(unit_details[Asking Rent],unit_details[Leased Date], ">=" & ($Q$2 - 7), unit_details[Leased Date], "<" & $Q$2, unit_details[Beds], 3, unit_details[Property Name], B10),"") | I13: =IFERROR( AVERAGEIFS(unit_details[Asking Rent], unit_details[Leased Date], ">=" & ($Q$2 - 7), unit_details[Leased Date], "<" & $Q$2, unit_details[Beds], 3, unit_details[Property Name], B10) - AVERAGEIFS(unit_details[Asking Rent], unit_details[Leased Date], ">=" & ($Q$2 - 14), unit_details[Leased Date], "<=" & ($Q$2 - 7), unit_details[Beds], 3, unit_details[Property Name], B10), 0) -> 0 | J13: =IFERROR(I13/AVERAGEIFS(unit_details[Asking Rent], unit_details[Leased Date], ">=" & ($Q$2 - 14), unit_details[Leased Date], "<=" & ($Q$2 - 7), unit_details[Beds], 3, unit_details[Property Name], B10),0) -> 0 | K13: =COUNTIFS(unit_details[First Listed], ">=" & ($Q$2 - 7), unit_details[First Listed], "<" & $Q$2, unit_details[Beds], 3, unit_details[Property Name], B10) -> 0 | L13: =COUNTIFS( unit_details[First Listed], ">=" & ($Q$2 - 7), unit_details[First Listed], "<" & $Q$2, unit_details[Beds], 3, unit_details[Property Name], B10 ) - COUNTIFS( unit_details[First Listed], ">=" & ($Q$2 - 14), unit_details[First Listed], "<=" & ($Q$2 - 7), unit_details[Beds], 3, unit_details[Property Name], B10 ) -> 0 | M13: =IFERROR(AVERAGEIFS(unit_details[Asking Rent],unit_details[First Listed],">="&($Q$2-7), unit_details[First Listed],"<="&$Q$2, unit_details[Beds],3, unit_details[Property Name],B10),"") | N13: =COUNTIFS(unit_details[Property Name], B10, unit_details[Beds], 3, unit_details[Leased Date], "") -> 0 | O13: =N13-(N13-K13+F13) -> 0 | P13: =IFERROR(AVERAGEIFS(unit_details[Asking Rent],unit_details[Property Name], B10, unit_details[Beds], 3, unit_details[Leased Date], ""),"") | Q13: =IFERROR(N13/SUMIFS(unit_mix_table['# Units],unit_mix_table[Beds],3,unit_mix_table[Property Name],B10),"")
B14: =IF(ISBLANK(OFFSET('Rent Comparison'!$A$1,2,7)),"",IF(OFFSET('Rent Comparison'!$A$1,2,7)=0,B15,OFFSET('Rent Comparison'!$A$1,2,7))) | C14: =IF(ISBLANK(B14),"",IFERROR(INDEX(Specials!B:J,MATCH(B14&" - Active",Specials!I:I,0),2),"")) | E14: Studio | F14: =COUNTIFS(unit_details[Leased Date], ">=" & ($Q$2 - 7), unit_details[Leased Date], "<" & $Q$2, unit_details[Beds], 0, unit_details[Property Name], B14) -> 0 | G14: =COUNTIFS(unit_details[Leased Date], ">=" & ($Q$2 - 7), unit_details[Leased Date], "<" & $Q$2, unit_details[Beds], 0, unit_details[Property Name], B14) - COUNTIFS(unit_details[Leased Date], ">=" & ($Q$2 - 14), unit_details[Leased Date], "<=" & ($Q$2 - 7), unit_details[Beds], 0, unit_details[Property Name], B14) -> 0 | H14: =IFERROR(AVERAGEIFS(unit_details[Asking Rent],unit_details[Leased Date], ">=" & ($Q$2 - 7), unit_details[Leased Date], "<" & $Q$2, unit_details[Beds], 0, unit_details[Property Name], B14),"") | I14: =IFERROR( AVERAGEIFS(unit_details[Asking Rent], unit_details[Leased Date], ">=" & ($Q$2 - 7), unit_details[Leased Date], "<" & $Q$2, unit_details[Beds], 0, unit_details[Property Name], B14) - AVERAGEIFS(unit_details[Asking Rent], unit_details[Leased Date], ">=" & ($Q$2 - 14), unit_details[Leased Date], "<=" & ($Q$2 - 7), unit_details[Beds], 0, unit_details[Property Name], B14), 0) -> 0 | J14: =IFERROR(I14/AVERAGEIFS(unit_details[Asking Rent], unit_details[Leased Date], ">=" & ($Q$2 - 14), unit_details[Leased Date], "<=" & ($Q$2 - 7), unit_details[Beds], 0, unit_details[Property Name], B14),0) -> 0 | K14: =COUNTIFS(unit_details[First Listed], ">=" & ($Q$2 - 7), unit_details[First Listed], "<" & $Q$2, unit_details[Beds], 0, unit_details[Property Name], B14) -> 0 | L14: =COUNTIFS( unit_details[First Listed], ">=" & ($Q$2 - 7), unit_details[First Listed], "<" & $Q$2, unit_details[Beds], 0, unit_details[Property Name], B14 ) - COUNTIFS( unit_details[First Listed], ">=" & ($Q$2 - 14), unit_details[First Listed], "<=" & ($Q$2 - 7), unit_details[Beds], 0, unit_details[Property Name], B14 ) -> 0 | M14: =IFERROR(AVERAGEIFS(unit_details[Asking Rent],unit_details[First Listed],">="&($Q$2-7), unit_details[First Listed],"<="&$Q$2, unit_details[Beds],0, unit_details[Property Name],B14),"") | N14: =COUNTIFS(unit_details[Property Name], B14, unit_details[Beds], 0, unit_details[Leased Date], "") -> 0 | O14: =N14-(N14-K14+F14) -> 0 | P14: =IFERROR(AVERAGEIFS(unit_details[Asking Rent],unit_details[Property Name], B14, unit_details[Beds], 0, unit_details[Leased Date], ""),"") | Q14: =IFERROR(N14/SUMIFS(unit_mix_table['# Units],unit_mix_table[Beds],0,unit_mix_table[Property Name],B14),"")
B15: 920 East 7th Street, Delta, CO 81416 | E15: 1 BR | F15: =COUNTIFS(unit_details[Leased Date], ">=" & ($Q$2 - 7), unit_details[Leased Date], "<" & $Q$2, unit_details[Beds], 1, unit_details[Property Name], B14) -> 0 | G15: =COUNTIFS(unit_details[Leased Date], ">=" & ($Q$2 - 7), unit_details[Leased Date], "<" & $Q$2, unit_details[Beds], 1, unit_details[Property Name], B14) - COUNTIFS(unit_details[Leased Date], ">=" & ($Q$2 - 14), unit_details[Leased Date], "<=" & ($Q$2 - 7), unit_details[Beds], 1, unit_details[Property Name], B14) -> 0 | H15: =IFERROR(AVERAGEIFS(unit_details[Asking Rent],unit_details[Leased Date], ">=" & ($Q$2 - 7), unit_details[Leased Date], "<" & $Q$2, unit_details[Beds], 1, unit_details[Property Name], B14),"") | I15: =IFERROR( AVERAGEIFS(unit_details[Asking Rent], unit_details[Leased Date], ">=" & ($Q$2 - 7), unit_details[Leased Date], "<" & $Q$2, unit_details[Beds], 1, unit_details[Property Name], B14) - AVERAGEIFS(unit_details[Asking Rent], unit_details[Leased Date], ">=" & ($Q$2 - 14), unit_details[Leased Date], "<=" & ($Q$2 - 7), unit_details[Beds], 1, unit_details[Property Name], B14), 0) -> 0 | J15: =IFERROR(I15/AVERAGEIFS(unit_details[Asking Rent], unit_details[Leased Date], ">=" & ($Q$2 - 14), unit_details[Leased Date], "<=" & ($Q$2 - 7), unit_details[Beds], 1, unit_details[Property Name], B14),0) -> 0 | K15: =COUNTIFS(unit_details[First Listed], ">=" & ($Q$2 - 7), unit_details[First Listed], "<" & $Q$2, unit_details[Beds], 1, unit_details[Property Name], B14) -> 0 | L15: =COUNTIFS( unit_details[First Listed], ">=" & ($Q$2 - 7), unit_details[First Listed], "<" & $Q$2, unit_details[Beds], 1, unit_details[Property Name], B14 ) - COUNTIFS( unit_details[First Listed], ">=" & ($Q$2 - 14), unit_details[First Listed], "<=" & ($Q$2 - 7), unit_details[Beds], 1, unit_details[Property Name], B14 ) -> 0 | M15: =IFERROR(AVERAGEIFS(unit_details[Asking Rent],unit_details[First Listed],">="&($Q$2-7), unit_details[First Listed],"<="&$Q$2, unit_details[Beds],1, unit_details[Property Name],B14),"") | N15: =COUNTIFS(unit_details[Property Name], B14, unit_details[Beds], 1, unit_details[Leased Date], "") -> 7 | O15: =N15-(N15-K15+F15) -> 0 | P15: =IFERROR(AVERAGEIFS(unit_details[Asking Rent],unit_details[Property Name], B14, unit_details[Beds], 1, unit_details[Leased Date], ""),"") -> 1028.5714 | Q15: =IFERROR(N15/SUMIFS(unit_mix_table['# Units],unit_mix_table[Beds],1,unit_mix_table[Property Name],B14),"") -> 2.3333333
E16: 2 BR | F16: =COUNTIFS(unit_details[Leased Date], ">=" & ($Q$2 - 7), unit_details[Leased Date], "<" & $Q$2, unit_details[Beds], 2, unit_details[Property Name], B14) -> 0 | G16: =COUNTIFS(unit_details[Leased Date], ">=" & ($Q$2 - 7), unit_details[Leased Date], "<" & $Q$2, unit_details[Beds], 2, unit_details[Property Name], B14) - COUNTIFS(unit_details[Leased Date], ">=" & ($Q$2 - 14), unit_details[Leased Date], "<=" & ($Q$2 - 7), unit_details[Beds], 2, unit_details[Property Name], B14) -> 0 | H16: =IFERROR(AVERAGEIFS(unit_details[Asking Rent],unit_details[Leased Date], ">=" & ($Q$2 - 7), unit_details[Leased Date], "<" & $Q$2, unit_details[Beds], 2, unit_details[Property Name], B14),"") | I16: =IFERROR( AVERAGEIFS(unit_details[Asking Rent], unit_details[Leased Date], ">=" & ($Q$2 - 7), unit_details[Leased Date], "<" & $Q$2, unit_details[Beds], 2, unit_details[Property Name], B14) - AVERAGEIFS(unit_details[Asking Rent], unit_details[Leased Date], ">=" & ($Q$2 - 14), unit_details[Leased Date], "<=" & ($Q$2 - 7), unit_details[Beds], 2, unit_details[Property Name], B14), 0) -> 0 | J16: =IFERROR(I16/AVERAGEIFS(unit_details[Asking Rent], unit_details[Leased Date], ">=" & ($Q$2 - 14), unit_details[Leased Date], "<=" & ($Q$2 - 7), unit_details[Beds], 2, unit_details[Property Name], B14),0) -> 0 | K16: =COUNTIFS(unit_details[First Listed], ">=" & ($Q$2 - 7), unit_details[First Listed], "<" & $Q$2, unit_details[Beds], 2, unit_details[Property Name], B14) -> 0 | L16: =COUNTIFS( unit_details[First Listed], ">=" & ($Q$2 - 7), unit_details[First Listed], "<" & $Q$2, unit_details[Beds], 2, unit_details[Property Name], B14 ) - COUNTIFS( unit_details[First Listed], ">=" & ($Q$2 - 14), unit_details[First Listed], "<=" & ($Q$2 - 7), unit_details[Beds], 2, unit_details[Property Name], B14 ) -> 0 | M16: =IFERROR(AVERAGEIFS(unit_details[Asking Rent],unit_details[First Listed],">="&($Q$2-7), unit_details[First Listed],"<="&$Q$2, unit_details[Beds],2, unit_details[Property Name],B14),"") | N16: =COUNTIFS(unit_details[Property Name], B14, unit_details[Beds], 2, unit_details[Leased Date], "") -> 9 | O16: =N16-(N16-K16+F16) -> 0 | P16: =IFERROR(AVERAGEIFS(unit_details[Asking Rent],unit_details[Property Name], B14, unit_details[Beds], 2, unit_details[Leased Date], ""),"") -> 1211.1111 | Q16: =IFERROR(N16/SUMIFS(unit_mix_table['# Units],unit_mix_table[Beds],2,unit_mix_table[Property Name],B14),"") -> 1.5
E17: 3 BR | F17: =COUNTIFS(unit_details[Leased Date], ">=" & ($Q$2 - 7), unit_details[Leased Date], "<" & $Q$2, unit_details[Beds], 3, unit_details[Property Name], B14) -> 0 | G17: =COUNTIFS(unit_details[Leased Date], ">=" & ($Q$2 - 7), unit_details[Leased Date], "<" & $Q$2, unit_details[Beds], 3, unit_details[Property Name], B14) - COUNTIFS(unit_details[Leased Date], ">=" & ($Q$2 - 14), unit_details[Leased Date], "<=" & ($Q$2 - 7), unit_details[Beds], 3, unit_details[Property Name], B14) -> 0 | H17: =IFERROR(AVERAGEIFS(unit_details[Asking Rent],unit_details[Leased Date], ">=" & ($Q$2 - 7), unit_details[Leased Date], "<" & $Q$2, unit_details[Beds], 3, unit_details[Property Name], B14),"") | I17: =IFERROR( AVERAGEIFS(unit_details[Asking Rent], unit_details[Leased Date], ">=" & ($Q$2 - 7), unit_details[Leased Date], "<" & $Q$2, unit_details[Beds], 3, unit_details[Property Name], B14) - AVERAGEIFS(unit_details[Asking Rent], unit_details[Leased Date], ">=" & ($Q$2 - 14), unit_details[Leased Date], "<=" & ($Q$2 - 7), unit_details[Beds], 3, unit_details[Property Name], B14), 0) -> 0 | J17: =IFERROR(I17/AVERAGEIFS(unit_details[Asking Rent], unit_details[Leased Date], ">=" & ($Q$2 - 14), unit_details[Leased Date], "<=" & ($Q$2 - 7), unit_details[Beds], 3, unit_details[Property Name], B14),0) -> 0 | K17: =COUNTIFS(unit_details[First Listed], ">=" & ($Q$2 - 7), unit_details[First Listed], "<" & $Q$2, unit_details[Beds], 3, unit_details[Property Name], B14) -> 0 | L17: =COUNTIFS( unit_details[First Listed], ">=" & ($Q$2 - 7), unit_details[First Listed], "<" & $Q$2, unit_details[Beds], 3, unit_details[Property Name], B14 ) - COUNTIFS( unit_details[First Listed], ">=" & ($Q$2 - 14), unit_details[First Listed], "<=" & ($Q$2 - 7), unit_details[Beds], 3, unit_details[Property Name], B14 ) -> 0 | M17: =IFERROR(AVERAGEIFS(unit_details[Asking Rent],unit_details[First Listed],">="&($Q$2-7), unit_details[First Listed],"<="&$Q$2, unit_details[Beds],3, unit_details[Property Name],B14),"") | N17: =COUNTIFS(unit_details[Property Name], B14, unit_details[Beds], 3, unit_details[Leased Date], "") -> 0 | O17: =N17-(N17-K17+F17) -> 0 | P17: =IFERROR(AVERAGEIFS(unit_details[Asking Rent],unit_details[Property Name], B14, unit_details[Beds], 3, unit_details[Leased Date], ""),"") | Q17: =IFERROR(N17/SUMIFS(unit_mix_table['# Units],unit_mix_table[Beds],3,unit_mix_table[Property Name],B14),"")
B18: =IF(ISBLANK(OFFSET('Rent Comparison'!$A$1,2,8)),"",IF(OFFSET('Rent Comparison'!$A$1,2,8)=0,B19,OFFSET('Rent Comparison'!$A$1,2,8))) | C18: =IF(ISBLANK(B18),"",IFERROR(INDEX(Specials!B:J,MATCH(B18&" - Active",Specials!I:I,0),2),"")) | E18: Studio | F18: =COUNTIFS(unit_details[Leased Date], ">=" & ($Q$2 - 7), unit_details[Leased Date], "<" & $Q$2, unit_details[Beds], 0, unit_details[Property Name], B18) -> 0 | G18: =COUNTIFS(unit_details[Leased Date], ">=" & ($Q$2 - 7), unit_details[Leased Date], "<" & $Q$2, unit_details[Beds], 0, unit_details[Property Name], B18) - COUNTIFS(unit_details[Leased Date], ">=" & ($Q$2 - 14), unit_details[Leased Date], "<=" & ($Q$2 - 7), unit_details[Beds], 0, unit_details[Property Name], B18) -> 0 | H18: =IFERROR(AVERAGEIFS(unit_details[Asking Rent],unit_details[Leased Date], ">=" & ($Q$2 - 7), unit_details[Leased Date], "<" & $Q$2, unit_details[Beds], 0, unit_details[Property Name], B18),"") | I18: =IFERROR( AVERAGEIFS(unit_details[Asking Rent], unit_details[Leased Date], ">=" & ($Q$2 - 7), unit_details[Leased Date], "<" & $Q$2, unit_details[Beds], 0, unit_details[Property Name], B18) - AVERAGEIFS(unit_details[Asking Rent], unit_details[Leased Date], ">=" & ($Q$2 - 14), unit_details[Leased Date], "<=" & ($Q$2 - 7), unit_details[Beds], 0, unit_details[Property Name], B18), 0) -> 0 | J18: =IFERROR(I18/AVERAGEIFS(unit_details[Asking Rent], unit_details[Leased Date], ">=" & ($Q$2 - 14), unit_details[Leased Date], "<=" & ($Q$2 - 7), unit_details[Beds], 0, unit_details[Property Name], B18),0) -> 0 | K18: =COUNTIFS(unit_details[First Listed], ">=" & ($Q$2 - 7), unit_details[First Listed], "<" & $Q$2, unit_details[Beds], 0, unit_details[Property Name], B18) -> 0 | L18: =COUNTIFS( unit_details[First Listed], ">=" & ($Q$2 - 7), unit_details[First Listed], "<" & $Q$2, unit_details[Beds], 0, unit_details[Property Name], B18 ) - COUNTIFS( unit_details[First Listed], ">=" & ($Q$2 - 14), unit_details[First Listed], "<=" & ($Q$2 - 7), unit_details[Beds], 0, unit_details[Property Name], B18 ) -> 0 | M18: =IFERROR(AVERAGEIFS(unit_details[Asking Rent],unit_details[First Listed],">="&($Q$2-7), unit_details[First Listed],"<="&$Q$2, unit_details[Beds],0, unit_details[Property Name],B18),"") | N18: =COUNTIFS(unit_details[Property Name], B18, unit_details[Beds], 0, unit_details[Leased Date], "") -> 0 | O18: =N18-(N18-K18+F18) -> 0 | P18: =IFERROR(AVERAGEIFS(unit_details[Asking Rent],unit_details[Property Name], B18, unit_details[Beds], 0, unit_details[Leased Date], ""),"") | Q18: =IFERROR(N18/SUMIFS(unit_mix_table['# Units],unit_mix_table[Beds],0,unit_mix_table[Property Name],B18),"")
B19: 217 Rich Street, Delta, CO 81416 | E19: 1 BR | F19: =COUNTIFS(unit_details[Leased Date], ">=" & ($Q$2 - 7), unit_details[Leased Date], "<" & $Q$2, unit_details[Beds], 1, unit_details[Property Name], B18) -> 0 | G19: =COUNTIFS(unit_details[Leased Date], ">=" & ($Q$2 - 7), unit_details[Leased Date], "<" & $Q$2, unit_details[Beds], 1, unit_details[Property Name], B18) - COUNTIFS(unit_details[Leased Date], ">=" & ($Q$2 - 14), unit_details[Leased Date], "<=" & ($Q$2 - 7), unit_details[Beds], 1, unit_details[Property Name], B18) -> 0 | H19: =IFERROR(AVERAGEIFS(unit_details[Asking Rent],unit_details[Leased Date], ">=" & ($Q$2 - 7), unit_details[Leased Date], "<" & $Q$2, unit_details[Beds], 1, unit_details[Property Name], B18),"") | I19: =IFERROR( AVERAGEIFS(unit_details[Asking Rent], unit_details[Leased Date], ">=" & ($Q$2 - 7), unit_details[Leased Date], "<" & $Q$2, unit_details[Beds], 1, unit_details[Property Name], B18) - AVERAGEIFS(unit_details[Asking Rent], unit_details[Leased Date], ">=" & ($Q$2 - 14), unit_details[Leased Date], "<=" & ($Q$2 - 7), unit_details[Beds], 1, unit_details[Property Name], B18), 0) -> 0 | J19: =IFERROR(I19/AVERAGEIFS(unit_details[Asking Rent], unit_details[Leased Date], ">=" & ($Q$2 - 14), unit_details[Leased Date], "<=" & ($Q$2 - 7), unit_details[Beds], 1, unit_details[Property Name], B18),0) -> 0 | K19: =COUNTIFS(unit_details[First Listed], ">=" & ($Q$2 - 7), unit_details[First Listed], "<" & $Q$2, unit_details[Beds], 1, unit_details[Property Name], B18) -> 0 | L19: =COUNTIFS( unit_details[First Listed], ">=" & ($Q$2 - 7), unit_details[First Listed], "<" & $Q$2, unit_details[Beds], 1, unit_details[Property Name], B18 ) - COUNTIFS( unit_details[First Listed], ">=" & ($Q$2 - 14), unit_details[First Listed], "<=" & ($Q$2 - 7), unit_details[Beds], 1, unit_details[Property Name], B18 ) -> 0 | M19: =IFERROR(AVERAGEIFS(unit_details[Asking Rent],unit_details[First Listed],">="&($Q$2-7), unit_details[First Listed],"<="&$Q$2, unit_details[Beds],1, unit_details[Property Name],B18),"") | N19: =COUNTIFS(unit_details[Property Name], B18, unit_details[Beds], 1, unit_details[Leased Date], "") -> 7 | O19: =N19-(N19-K19+F19) -> 0 | P19: =IFERROR(AVERAGEIFS(unit_details[Asking Rent],unit_details[Property Name], B18, unit_details[Beds], 1, unit_details[Leased Date], ""),"") -> 1028.5714 | Q19: =IFERROR(N19/SUMIFS(unit_mix_table['# Units],unit_mix_table[Beds],1,unit_mix_table[Property Name],B18),"") -> 2.3333333
E20: 2 BR | F20: =COUNTIFS(unit_details[Leased Date], ">=" & ($Q$2 - 7), unit_details[Leased Date], "<" & $Q$2, unit_details[Beds], 2, unit_details[Property Name], B18) -> 0 | G20: =COUNTIFS(unit_details[Leased Date], ">=" & ($Q$2 - 7), unit_details[Leased Date], "<" & $Q$2, unit_details[Beds], 2, unit_details[Property Name], B18) - COUNTIFS(unit_details[Leased Date], ">=" & ($Q$2 - 14), unit_details[Leased Date], "<=" & ($Q$2 - 7), unit_details[Beds], 2, unit_details[Property Name], B18) -> 0 | H20: =IFERROR(AVERAGEIFS(unit_details[Asking Rent],unit_details[Leased Date], ">=" & ($Q$2 - 7), unit_details[Leased Date], "<" & $Q$2, unit_details[Beds], 2, unit_details[Property Name], B18),"") | I20: =IFERROR( AVERAGEIFS(unit_details[Asking Rent], unit_details[Leased Date], ">=" & ($Q$2 - 7), unit_details[Leased Date], "<" & $Q$2, unit_details[Beds], 2, unit_details[Property Name], B18) - AVERAGEIFS(unit_details[Asking Rent], unit_details[Leased Date], ">=" & ($Q$2 - 14), unit_details[Leased Date], "<=" & ($Q$2 - 7), unit_details[Beds], 2, unit_details[Property Name], B18), 0) -> 0 | J20: =IFERROR(I20/AVERAGEIFS(unit_details[Asking Rent], unit_details[Leased Date], ">=" & ($Q$2 - 14), unit_details[Leased Date], "<=" & ($Q$2 - 7), unit_details[Beds], 2, unit_details[Property Name], B18),0) -> 0 | K20: =COUNTIFS(unit_details[First Listed], ">=" & ($Q$2 - 7), unit_details[First Listed], "<" & $Q$2, unit_details[Beds], 2, unit_details[Property Name], B18) -> 0 | L20: =COUNTIFS( unit_details[First Listed], ">=" & ($Q$2 - 7), unit_details[First Listed], "<" & $Q$2, unit_details[Beds], 2, unit_details[Property Name], B18 ) - COUNTIFS( unit_details[First Listed], ">=" & ($Q$2 - 14), unit_details[First Listed], "<=" & ($Q$2 - 7), unit_details[Beds], 2, unit_details[Property Name], B18 ) -> 0 | M20: =IFERROR(AVERAGEIFS(unit_details[Asking Rent],unit_details[First Listed],">="&($Q$2-7), unit_details[First Listed],"<="&$Q$2, unit_details[Beds],2, unit_details[Property Name],B18),"") | N20: =COUNTIFS(unit_details[Property Name], B18, unit_details[Beds], 2, unit_details[Leased Date], "") -> 9 | O20: =N20-(N20-K20+F20) -> 0 | P20: =IFERROR(AVERAGEIFS(unit_details[Asking Rent],unit_details[Property Name], B18, unit_details[Beds], 2, unit_details[Leased Date], ""),"") -> 1211.1111 | Q20: =IFERROR(N20/SUMIFS(unit_mix_table['# Units],unit_mix_table[Beds],2,unit_mix_table[Property Name],B18),"") -> 1.5
E21: 3 BR | F21: =COUNTIFS(unit_details[Leased Date], ">=" & ($Q$2 - 7), unit_details[Leased Date], "<" & $Q$2, unit_details[Beds], 3, unit_details[Property Name], B18) -> 0 | G21: =COUNTIFS(unit_details[Leased Date], ">=" & ($Q$2 - 7), unit_details[Leased Date], "<" & $Q$2, unit_details[Beds], 3, unit_details[Property Name], B18) - COUNTIFS(unit_details[Leased Date], ">=" & ($Q$2 - 14), unit_details[Leased Date], "<=" & ($Q$2 - 7), unit_details[Beds], 3, unit_details[Property Name], B18) -> 0 | H21: =IFERROR(AVERAGEIFS(unit_details[Asking Rent],unit_details[Leased Date], ">=" & ($Q$2 - 7), unit_details[Leased Date], "<" & $Q$2, unit_details[Beds], 3, unit_details[Property Name], B18),"") | I21: =IFERROR( AVERAGEIFS(unit_details[Asking Rent], unit_details[Leased Date], ">=" & ($Q$2 - 7), unit_details[Leased Date], "<" & $Q$2, unit_details[Beds], 3, unit_details[Property Name], B18) - AVERAGEIFS(unit_details[Asking Rent], unit_details[Leased Date], ">=" & ($Q$2 - 14), unit_details[Leased Date], "<=" & ($Q$2 - 7), unit_details[Beds], 3, unit_details[Property Name], B18), 0) -> 0 | J21: =IFERROR(I21/AVERAGEIFS(unit_details[Asking Rent], unit_details[Leased Date], ">=" & ($Q$2 - 14), unit_details[Leased Date], "<=" & ($Q$2 - 7), unit_details[Beds], 3, unit_details[Property Name], B18),0) -> 0 | K21: =COUNTIFS(unit_details[First Listed], ">=" & ($Q$2 - 7), unit_details[First Listed], "<" & $Q$2, unit_details[Beds], 3, unit_details[Property Name], B18) -> 0 | L21: =COUNTIFS( unit_details[First Listed], ">=" & ($Q$2 - 7), unit_details[First Listed], "<" & $Q$2, unit_details[Beds], 3, unit_details[Property Name], B18 ) - COUNTIFS( unit_details[First Listed], ">=" & ($Q$2 - 14), unit_details[First Listed], "<=" & ($Q$2 - 7), unit_details[Beds], 3, unit_details[Property Name], B18 ) -> 0 | M21: =IFERROR(AVERAGEIFS(unit_details[Asking Rent],unit_details[First Listed],">="&($Q$2-7), unit_details[First Listed],"<="&$Q$2, unit_details[Beds],3, unit_details[Property Name],B18),"") | N21: =COUNTIFS(unit_details[Property Name], B18, unit_details[Beds], 3, unit_details[Leased Date], "") -> 0 | O21: =N21-(N21-K21+F21) -> 0 | P21: =IFERROR(AVERAGEIFS(unit_details[Asking Rent],unit_details[Property Name], B18, unit_details[Beds], 3, unit_details[Leased Date], ""),"") | Q21: =IFERROR(N21/SUMIFS(unit_mix_table['# Units],unit_mix_table[Beds],3,unit_mix_table[Property Name],B18),"")
B22: =IF(ISBLANK(OFFSET('Rent Comparison'!$A$1,2,9)),"",IF(OFFSET('Rent Comparison'!$A$1,2,9)=0,B23,OFFSET('Rent Comparison'!$A$1,2,9))) | C22: =IF(ISBLANK(B22),"",IFERROR(INDEX(Specials!B:J,MATCH(B22&" - Active",Specials!I:I,0),2),"")) | E22: Studio | F22: =COUNTIFS(unit_details[Leased Date], ">=" & ($Q$2 - 7), unit_details[Leased Date], "<" & $Q$2, unit_details[Beds], 0, unit_details[Property Name], B22) -> 0 | G22: =COUNTIFS(unit_details[Leased Date], ">=" & ($Q$2 - 7), unit_details[Leased Date], "<" & $Q$2, unit_details[Beds], 0, unit_details[Property Name], B22) - COUNTIFS(unit_details[Leased Date], ">=" & ($Q$2 - 14), unit_details[Leased Date], "<=" & ($Q$2 - 7), unit_details[Beds], 0, unit_details[Property Name], B22) -> 0 | H22: =IFERROR(AVERAGEIFS(unit_details[Asking Rent],unit_details[Leased Date], ">=" & ($Q$2 - 7), unit_details[Leased Date], "<" & $Q$2, unit_details[Beds], 0, unit_details[Property Name], B22),"") | I22: =IFERROR( AVERAGEIFS(unit_details[Asking Rent], unit_details[Leased Date], ">=" & ($Q$2 - 7), unit_details[Leased Date], "<" & $Q$2, unit_details[Beds], 0, unit_details[Property Name], B22) - AVERAGEIFS(unit_details[Asking Rent], unit_details[Leased Date], ">=" & ($Q$2 - 14), unit_details[Leased Date], "<=" & ($Q$2 - 7), unit_details[Beds], 0, unit_details[Property Name], B22), 0) -> 0 | J22: =IFERROR(I22/AVERAGEIFS(unit_details[Asking Rent], unit_details[Leased Date], ">=" & ($Q$2 - 14), unit_details[Leased Date], "<=" & ($Q$2 - 7), unit_details[Beds], 0, unit_details[Property Name], B22),0) -> 0 | K22: =COUNTIFS(unit_details[First Listed], ">=" & ($Q$2 - 7), unit_details[First Listed], "<" & $Q$2, unit_details[Beds], 0, unit_details[Property Name], B22) -> 0 | L22: =COUNTIFS( unit_details[First Listed], ">=" & ($Q$2 - 7), unit_details[First Listed], "<" & $Q$2, unit_details[Beds], 0, unit_details[Property Name], B22 ) - COUNTIFS( unit_details[First Listed], ">=" & ($Q$2 - 14), unit_details[First Listed], "<=" & ($Q$2 - 7), unit_details[Beds], 0, unit_details[Property Name], B22 ) -> 0 | M22: =IFERROR(AVERAGEIFS(unit_details[Asking Rent],unit_details[First Listed],">="&($Q$2-7), unit_details[First Listed],"<="&$Q$2, unit_details[Beds],0, unit_details[Property Name],B22),"") | N22: =COUNTIFS(unit_details[Property Name], B22, unit_details[Beds], 0, unit_details[Leased Date], "") -> 0 | O22: =N22-(N22-K22+F22) -> 0 | P22: =IFERROR(AVERAGEIFS(unit_details[Asking Rent],unit_details[Property Name], B22, unit_details[Beds], 0, unit_details[Leased Date], ""),"") | Q22: =IFERROR(N22/SUMIFS(unit_mix_table['# Units],unit_mix_table[Beds],0,unit_mix_table[Property Name],B22),"")
B23: 240 Meeker Street, Delta, CO 81416 | E23: 1 BR | F23: =COUNTIFS(unit_details[Leased Date], ">=" & ($Q$2 - 7), unit_details[Leased Date], "<" & $Q$2, unit_details[Beds], 1, unit_details[Property Name], B22) -> 0 | G23: =COUNTIFS(unit_details[Leased Date], ">=" & ($Q$2 - 7), unit_details[Leased Date], "<" & $Q$2, unit_details[Beds], 1, unit_details[Property Name], B22) - COUNTIFS(unit_details[Leased Date], ">=" & ($Q$2 - 14), unit_details[Leased Date], "<=" & ($Q$2 - 7), unit_details[Beds], 1, unit_details[Property Name], B22) -> 0 | H23: =IFERROR(AVERAGEIFS(unit_details[Asking Rent],unit_details[Leased Date], ">=" & ($Q$2 - 7), unit_details[Leased Date], "<" & $Q$2, unit_details[Beds], 1, unit_details[Property Name], B22),"") | I23: =IFERROR( AVERAGEIFS(unit_details[Asking Rent], unit_details[Leased Date], ">=" & ($Q$2 - 7), unit_details[Leased Date], "<" & $Q$2, unit_details[Beds], 1, unit_details[Property Name], B22) - AVERAGEIFS(unit_details[Asking Rent], unit_details[Leased Date], ">=" & ($Q$2 - 14), unit_details[Leased Date], "<=" & ($Q$2 - 7), unit_details[Beds], 1, unit_details[Property Name], B22), 0) -> 0 | J23: =IFERROR(I23/AVERAGEIFS(unit_details[Asking Rent], unit_details[Leased Date], ">=" & ($Q$2 - 14), unit_details[Leased Date], "<=" & ($Q$2 - 7), unit_details[Beds], 1, unit_details[Property Name], B22),0) -> 0 | K23: =COUNTIFS(unit_details[First Listed], ">=" & ($Q$2 - 7), unit_details[First Listed], "<" & $Q$2, unit_details[Beds], 1, unit_details[Property Name], B22) -> 0 | L23: =COUNTIFS( unit_details[First Listed], ">=" & ($Q$2 - 7), unit_details[First Listed], "<" & $Q$2, unit_details[Beds], 1, unit_details[Property Name], B22 ) - COUNTIFS( unit_details[First Listed], ">=" & ($Q$2 - 14), unit_details[First Listed], "<=" & ($Q$2 - 7), unit_details[Beds], 1, unit_details[Property Name], B22 ) -> 0 | M23: =IFERROR(AVERAGEIFS(unit_details[Asking Rent],unit_details[First Listed],">="&($Q$2-7), unit_details[First Listed],"<="&$Q$2, unit_details[Beds],1, unit_details[Property Name],B22),"") | N23: =COUNTIFS(unit_details[Property Name], B22, unit_details[Beds], 1, unit_details[Leased Date], "") -> 7 | O23: =N23-(N23-K23+F23) -> 0 | P23: =IFERROR(AVERAGEIFS(unit_details[Asking Rent],unit_details[Property Name], B22, unit_details[Beds], 1, unit_details[Leased Date], ""),"") -> 1028.5714 | Q23: =IFERROR(N23/SUMIFS(unit_mix_table['# Units],unit_mix_table[Beds],1,unit_mix_table[Property Name],B22),"") -> 2.3333333
E24: 2 BR | F24: =COUNTIFS(unit_details[Leased Date], ">=" & ($Q$2 - 7), unit_details[Leased Date], "<" & $Q$2, unit_details[Beds], 2, unit_details[Property Name], B22) -> 0 | G24: =COUNTIFS(unit_details[Leased Date], ">=" & ($Q$2 - 7), unit_details[Leased Date], "<" & $Q$2, unit_details[Beds], 2, unit_details[Property Name], B22) - COUNTIFS(unit_details[Leased Date], ">=" & ($Q$2 - 14), unit_details[Leased Date], "<=" & ($Q$2 - 7), unit_details[Beds], 2, unit_details[Property Name], B22) -> 0 | H24: =IFERROR(AVERAGEIFS(unit_details[Asking Rent],unit_details[Leased Date], ">=" & ($Q$2 - 7), unit_details[Leased Date], "<" & $Q$2, unit_details[Beds], 2, unit_details[Property Name], B22),"") | I24: =IFERROR( AVERAGEIFS(unit_details[Asking Rent], unit_details[Leased Date], ">=" & ($Q$2 - 7), unit_details[Leased Date], "<" & $Q$2, unit_details[Beds], 2, unit_details[Property Name], B22) - AVERAGEIFS(unit_details[Asking Rent], unit_details[Leased Date], ">=" & ($Q$2 - 14), unit_details[Leased Date], "<=" & ($Q$2 - 7), unit_details[Beds], 2, unit_details[Property Name], B22), 0) -> 0 | J24: =IFERROR(I24/AVERAGEIFS(unit_details[Asking Rent], unit_details[Leased Date], ">=" & ($Q$2 - 14), unit_details[Leased Date], "<=" & ($Q$2 - 7), unit_details[Beds], 2, unit_details[Property Name], B22),0) -> 0 | K24: =COUNTIFS(unit_details[First Listed], ">=" & ($Q$2 - 7), unit_details[First Listed], "<" & $Q$2, unit_details[Beds], 2, unit_details[Property Name], B22) -> 0 | L24: =COUNTIFS( unit_details[First Listed], ">=" & ($Q$2 - 7), unit_details[First Listed], "<" & $Q$2, unit_details[Beds], 2, unit_details[Property Name], B22 ) - COUNTIFS( unit_details[First Listed], ">=" & ($Q$2 - 14), unit_details[First Listed], "<=" & ($Q$2 - 7), unit_details[Beds], 2, unit_details[Property Name], B22 ) -> 0 | M24: =IFERROR(AVERAGEIFS(unit_details[Asking Rent],unit_details[First Listed],">="&($Q$2-7), unit_details[First Listed],"<="&$Q$2, unit_details[Beds],2, unit_details[Property Name],B22),"") | N24: =COUNTIFS(unit_details[Property Name], B22, unit_details[Beds], 2, unit_details[Leased Date], "") -> 9 | O24: =N24-(N24-K24+F24) -> 0 | P24: =IFERROR(AVERAGEIFS(unit_details[Asking Rent],unit_details[Property Name], B22, unit_details[Beds], 2, unit_details[Leased Date], ""),"") -> 1211.1111 | Q24: =IFERROR(N24/SUMIFS(unit_mix_table['# Units],unit_mix_table[Beds],2,unit_mix_table[Property Name],B22),"") -> 1.5
B25: https://areabest.net | E25: 3 BR | F25: =COUNTIFS(unit_details[Leased Date], ">=" & ($Q$2 - 7), unit_details[Leased Date], "<" & $Q$2, unit_details[Beds], 3, unit_details[Property Name], B22) -> 0 | G25: =COUNTIFS(unit_details[Leased Date], ">=" & ($Q$2 - 7), unit_details[Leased Date], "<" & $Q$2, unit_details[Beds], 3, unit_details[Property Name], B22) - COUNTIFS(unit_details[Leased Date], ">=" & ($Q$2 - 14), unit_details[Leased Date], "<=" & ($Q$2 - 7), unit_details[Beds], 3, unit_details[Property Name], B22) -> 0 | H25: =IFERROR(AVERAGEIFS(unit_details[Asking Rent],unit_details[Leased Date], ">=" & ($Q$2 - 7), unit_details[Leased Date], "<" & $Q$2, unit_details[Beds], 3, unit_details[Property Name], B22),"") | I25: =IFERROR( AVERAGEIFS(unit_details[Asking Rent], unit_details[Leased Date], ">=" & ($Q$2 - 7), unit_details[Leased Date], "<" & $Q$2, unit_details[Beds], 3, unit_details[Property Name], B22) - AVERAGEIFS(unit_details[Asking Rent], unit_details[Leased Date], ">=" & ($Q$2 - 14), unit_details[Leased Date], "<=" & ($Q$2 - 7), unit_details[Beds], 3, unit_details[Property Name], B22), 0) -> 0 | J25: =IFERROR(I25/AVERAGEIFS(unit_details[Asking Rent], unit_details[Leased Date], ">=" & ($Q$2 - 14), unit_details[Leased Date], "<=" & ($Q$2 - 7), unit_details[Beds], 3, unit_details[Property Name], B22),0) -> 0 | K25: =COUNTIFS(unit_details[First Listed], ">=" & ($Q$2 - 7), unit_details[First Listed], "<" & $Q$2, unit_details[Beds], 3, unit_details[Property Name], B22) -> 0 | L25: =COUNTIFS( unit_details[First Listed], ">=" & ($Q$2 - 7), unit_details[First Listed], "<" & $Q$2, unit_details[Beds], 3, unit_details[Property Name], B22 ) - COUNTIFS( unit_details[First Listed], ">=" & ($Q$2 - 14), unit_details[First Listed], "<=" & ($Q$2 - 7), unit_details[Beds], 3, unit_details[Property Name], B22 ) -> 0 | M25: =IFERROR(AVERAGEIFS(unit_details[Asking Rent],unit_details[First Listed],">="&($Q$2-7), unit_details[First Listed],"<="&$Q$2, unit_details[Beds],3, unit_details[Property Name],B22),"") | N25: =COUNTIFS(unit_details[Property Name], B22, unit_details[Beds], 3, unit_details[Leased Date], "") -> 0 | O25: =N25-(N25-K25+F25) -> 0 | P25: =IFERROR(AVERAGEIFS(unit_details[Asking Rent],unit_details[Property Name], B22, unit_details[Beds], 3, unit_details[Leased Date], ""),"") | Q25: =IFERROR(N25/SUMIFS(unit_mix_table['# Units],unit_mix_table[Beds],3,unit_mix_table[Property Name],B22),"")
B26: =IF(ISBLANK(OFFSET('Rent Comparison'!$A$1,2,10)),"",IF(OFFSET('Rent Comparison'!$A$1,2,10)=0,B27,OFFSET('Rent Comparison'!$A$1,2,10))) | C26: =IF(ISBLANK(B26),"",IFERROR(INDEX(Specials!B:J,MATCH(B26&" - Active",Specials!I:I,0),2),"")) | E26: Studio | F26: =COUNTIFS(unit_details[Leased Date], ">=" & ($Q$2 - 7), unit_details[Leased Date], "<" & $Q$2, unit_details[Beds], 0, unit_details[Property Name], B26) -> 0 | G26: =COUNTIFS(unit_details[Leased Date], ">=" & ($Q$2 - 7), unit_details[Leased Date], "<" & $Q$2, unit_details[Beds], 0, unit_details[Property Name], B26) - COUNTIFS(unit_details[Leased Date], ">=" & ($Q$2 - 14), unit_details[Leased Date], "<=" & ($Q$2 - 7), unit_details[Beds], 0, unit_details[Property Name], B26) -> 0 | H26: =IFERROR(AVERAGEIFS(unit_details[Asking Rent],unit_details[Leased Date], ">=" & ($Q$2 - 7), unit_details[Leased Date], "<" & $Q$2, unit_details[Beds], 0, unit_details[Property Name], B26),"") | I26: =IFERROR( AVERAGEIFS(unit_details[Asking Rent], unit_details[Leased Date], ">=" & ($Q$2 - 7), unit_details[Leased Date], "<" & $Q$2, unit_details[Beds], 0, unit_details[Property Name], B26) - AVERAGEIFS(unit_details[Asking Rent], unit_details[Leased Date], ">=" & ($Q$2 - 14), unit_details[Leased Date], "<=" & ($Q$2 - 7), unit_details[Beds], 0, unit_details[Property Name], B26), 0) -> 0 | J26: =IFERROR(I26/AVERAGEIFS(unit_details[Asking Rent], unit_details[Leased Date], ">=" & ($Q$2 - 14), unit_details[Leased Date], "<=" & ($Q$2 - 7), unit_details[Beds], 0, unit_details[Property Name], B26),0) -> 0 | K26: =COUNTIFS(unit_details[First Listed], ">=" & ($Q$2 - 7), unit_details[First Listed], "<" & $Q$2, unit_details[Beds], 0, unit_details[Property Name], B26) -> 0 | L26: =COUNTIFS( unit_details[First Listed], ">=" & ($Q$2 - 7), unit_details[First Listed], "<" & $Q$2, unit_details[Beds], 0, unit_details[Property Name], B26 ) - COUNTIFS( unit_details[First Listed], ">=" & ($Q$2 - 14), unit_details[First Listed], "<=" & ($Q$2 - 7), unit_details[Beds], 0, unit_details[Property Name], B26 ) -> 0 | M26: =IFERROR(AVERAGEIFS(unit_details[Asking Rent],unit_details[First Listed],">="&($Q$2-7), unit_details[First Listed],"<="&$Q$2, unit_details[Beds],0, unit_details[Property Name],B26),"") | N26: =COUNTIFS(unit_details[Property Name], B26, unit_details[Beds], 0, unit_details[Leased Date], "") -> 0 | O26: =N26-(N26-K26+F26) -> 0 | P26: =IFERROR(AVERAGEIFS(unit_details[Asking Rent],unit_details[Property Name], B26, unit_details[Beds], 0, unit_details[Leased Date], ""),"") | Q26: =IFERROR(N26/SUMIFS(unit_mix_table['# Units],unit_mix_table[Beds],0,unit_mix_table[Property Name],B26),"")
B27: 260 Meeker Street, Delta, CO 81416 | E27: 1 BR | F27: =COUNTIFS(unit_details[Leased Date], ">=" & ($Q$2 - 7), unit_details[Leased Date], "<" & $Q$2, unit_details[Beds], 1, unit_details[Property Name], B26) -> 0 | G27: =COUNTIFS(unit_details[Leased Date], ">=" & ($Q$2 - 7), unit_details[Leased Date], "<" & $Q$2, unit_details[Beds], 1, unit_details[Property Name], B26) - COUNTIFS(unit_details[Leased Date], ">=" & ($Q$2 - 14), unit_details[Leased Date], "<=" & ($Q$2 - 7), unit_details[Beds], 1, unit_details[Property Name], B26) -> 0 | H27: =IFERROR(AVERAGEIFS(unit_details[Asking Rent],unit_details[Leased Date], ">=" & ($Q$2 - 7), unit_details[Leased Date], "<" & $Q$2, unit_details[Beds], 1, unit_details[Property Name], B26),"") | I27: =IFERROR( AVERAGEIFS(unit_details[Asking Rent], unit_details[Leased Date], ">=" & ($Q$2 - 7), unit_details[Leased Date], "<" & $Q$2, unit_details[Beds], 1, unit_details[Property Name], B26) - AVERAGEIFS(unit_details[Asking Rent], unit_details[Leased Date], ">=" & ($Q$2 - 14), unit_details[Leased Date], "<=" & ($Q$2 - 7), unit_details[Beds], 1, unit_details[Property Name], B26), 0) -> 0 | J27: =IFERROR(I27/AVERAGEIFS(unit_details[Asking Rent], unit_details[Leased Date], ">=" & ($Q$2 - 14), unit_details[Leased Date], "<=" & ($Q$2 - 7), unit_details[Beds], 1, unit_details[Property Name], B26),0) -> 0 | K27: =COUNTIFS(unit_details[First Listed], ">=" & ($Q$2 - 7), unit_details[First Listed], "<" & $Q$2, unit_details[Beds], 1, unit_details[Property Name], B26) -> 0 | L27: =COUNTIFS( unit_details[First Listed], ">=" & ($Q$2 - 7), unit_details[First Listed], "<" & $Q$2, unit_details[Beds], 1, unit_details[Property Name], B26 ) - COUNTIFS( unit_details[First Listed], ">=" & ($Q$2 - 14), unit_details[First Listed], "<=" & ($Q$2 - 7), unit_details[Beds], 1, unit_details[Property Name], B26 ) -> 0 | M27: =IFERROR(AVERAGEIFS(unit_details[Asking Rent],unit_details[First Listed],">="&($Q$2-7), unit_details[First Listed],"<="&$Q$2, unit_details[Beds],1, unit_details[Property Name],B26),"") | N27: =COUNTIFS(unit_details[Property Name], B26, unit_details[Beds], 1, unit_details[Leased Date], "") -> 7 | O27: =N27-(N27-K27+F27) -> 0 | P27: =IFERROR(AVERAGEIFS(unit_details[Asking Rent],unit_details[Property Name], B26, unit_details[Beds], 1, unit_details[Leased Date], ""),"") -> 1028.5714 | Q27: =IFERROR(N27/SUMIFS(unit_mix_table['# Units],unit_mix_table[Beds],1,unit_mix_table[Property Name],B26),"") -> 2.3333333
E28: 2 BR | F28: =COUNTIFS(unit_details[Leased Date], ">=" & ($Q$2 - 7), unit_details[Leased Date], "<" & $Q$2, unit_details[Beds], 2, unit_details[Property Name], B26) -> 0 | G28: =COUNTIFS(unit_details[Leased Date], ">=" & ($Q$2 - 7), unit_details[Leased Date], "<" & $Q$2, unit_details[Beds], 2, unit_details[Property Name], B26) - COUNTIFS(unit_details[Leased Date], ">=" & ($Q$2 - 14), unit_details[Leased Date], "<=" & ($Q$2 - 7), unit_details[Beds], 2, unit_details[Property Name], B26) -> 0 | H28: =IFERROR(AVERAGEIFS(unit_details[Asking Rent],unit_details[Leased Date], ">=" & ($Q$2 - 7), unit_details[Leased Date], "<" & $Q$2, unit_details[Beds], 2, unit_details[Property Name], B26),"") | I28: =IFERROR( AVERAGEIFS(unit_details[Asking Rent], unit_details[Leased Date], ">=" & ($Q$2 - 7), unit_details[Leased Date], "<" & $Q$2, unit_details[Beds], 2, unit_details[Property Name], B26) - AVERAGEIFS(unit_details[Asking Rent], unit_details[Leased Date], ">=" & ($Q$2 - 14), unit_details[Leased Date], "<=" & ($Q$2 - 7), unit_details[Beds], 2, unit_details[Property Name], B26), 0) -> 0 | J28: =IFERROR(I28/AVERAGEIFS(unit_details[Asking Rent], unit_details[Leased Date], ">=" & ($Q$2 - 14), unit_details[Leased Date], "<=" & ($Q$2 - 7), unit_details[Beds], 2, unit_details[Property Name], B26),0) -> 0 | K28: =COUNTIFS(unit_details[First Listed], ">=" & ($Q$2 - 7), unit_details[First Listed], "<" & $Q$2, unit_details[Beds], 2, unit_details[Property Name], B26) -> 0 | L28: =COUNTIFS( unit_details[First Listed], ">=" & ($Q$2 - 7), unit_details[First Listed], "<" & $Q$2, unit_details[Beds], 2, unit_details[Property Name], B26 ) - COUNTIFS( unit_details[First Listed], ">=" & ($Q$2 - 14), unit_details[First Listed], "<=" & ($Q$2 - 7), unit_details[Beds], 2, unit_details[Property Name], B26 ) -> 0 | M28: =IFERROR(AVERAGEIFS(unit_details[Asking Rent],unit_details[First Listed],">="&($Q$2-7), unit_details[First Listed],"<="&$Q$2, unit_details[Beds],2, unit_details[Property Name],B26),"") | N28: =COUNTIFS(unit_details[Property Name], B26, unit_details[Beds], 2, unit_details[Leased Date], "") -> 9 | O28: =N28-(N28-K28+F28) -> 0 | P28: =IFERROR(AVERAGEIFS(unit_details[Asking Rent],unit_details[Property Name], B26, unit_details[Beds], 2, unit_details[Leased Date], ""),"") -> 1211.1111 | Q28: =IFERROR(N28/SUMIFS(unit_mix_table['# Units],unit_mix_table[Beds],2,unit_mix_table[Property Name],B26),"") -> 1.5
